Workbook

Sheet RAW DATA
A1: ID Karyawan (Auto Generate) | B1: Nama Karyawan (sesuai KTP) | C1: Alamat sesuai KTP | D1: Tanggal Lahir | E1: Kota Kelahiran | F1: Pendidikan Terakhir | G1: No WA (Aktif) | H1: Alamat Email (Aktif) | I1: Nama Jabatan | J1: Nama Lokasi kerja (jika promotor sebutkan nama toko penempatan) | K1: Nama Kota/ Kabupaten Lokasi Kerja | L1: No Rekening BCA (Aktif) | M1: Tgl join di Mito | N1: Tgl awal kontrak (dg Damarindo) | O1: Tgl akhir kontrak (StaffInc) | P1: Nama Cabang (Cost Center) | Q1: Entity | R1: Skema Penggajian | S1: Nominal UMK yang dipakai | T1: Amount Gaji Pokok | U1: Amount Insentif 30% | V1: Remarks | W1: Basic Salary (StaffInc) | X1: Tunjangan (StaffInc) | Y1: Total
A2: DM20260001 | B2: Abel Saskia Putri | C2: =vlookup(B2,Sheet3!B:C,2,0) -> Jln. Jelawat | D2: =vlookup(B2,Sheet3!B:D,3,0) -> 39148 | E2: =vlookup(B2,Sheet3!B:F,5,0) -> Samarinda | F2: =vlookup(B2,Sheet3!B:H,7,0) -> SLTA | G2: =vlookup(B2,Sheet3!B:I,8,0) -> 088705334961 | H2: =vlookup(B2,Sheet3!B:J,9,0) -> bypisbel7@gmail.com | I2: SPB/SPG Toko | J2: =vlookup(B2,Sheet2!B:D,3,0) -> MAMASUKA | K2: =vlookup(A2,Sheet2!A:E,5,0) -> SAMARINDA | L2: =VLOOKUP(B2,Sheet3!B:L,11,0) -> 8355484218 | M2: 46280 | N2: 46280 | P2: =VLOOKUP(A2,Sheet2!A:F,6,0) -> SAMARINDA | Q2: PT. Mahakarya Sukses Indonesia | R2: 70/30 | S2: 3984000 | T2: 2788800 | U2: 1195200 | V2: Resign per 20/9 | Y2: =W2+X2 -> 0
A3: DM20260002 | B3: Adelina Astuti | C3: =vlookup(B3,Sheet3!B:C,2,0) -> Dusun Tamansari RT 012 / RW 004 ,kel. Kertahayu kec. Pamarican | D3: =vlookup(B3,Sheet3!B:D,3,0) -> 33737 | E3: =vlookup(B3,Sheet3!B:F,5,0) -> CIAMIS | F3: =vlookup(B3,Sheet3!B:H,7,0) -> SLTA | G3: =vlookup(B3,Sheet3!B:I,8,0) -> 085849233099 | H3: =vlookup(B3,Sheet3!B:J,9,0) -> Adelinemeidian@gmail.com | I3: SPB/SPG Outlet | J3: =vlookup(B3,Sheet2!B:D,3,0) -> MALL KELAPA GADING | K3: =vlookup(A3,Sheet2!A:E,5,0) -> JAKARTA | L3: =VLOOKUP(B3,Sheet3!B:L,11,0) -> 5910185235 | M3: 44852 | N3: 46266 | O3: 46265 | P3: =VLOOKUP(A3,Sheet2!A:F,6,0) -> JAKARTA | Q3: PT. Mahakarya Sukses Indonesia | R3: Khusus | S3: 5730000 | T3: 5730000 | W3: 5729876 | X3: 600000 | Y3: =W3+X3 -> 6329876
A4: DM20260003 | B4: Agustia Ningrum | C4: =vlookup(B4,Sheet3!B:C,2,0) -> JL.KASAN REJO 2 | D4: =vlookup(B4,Sheet3!B:D,3,0) -> 36395 | E4: =vlookup(B4,Sheet3!B:F,5,0) -> JEPARA | F4: =vlookup(B4,Sheet3!B:H,7,0) -> SLTA | G4: =vlookup(B4,Sheet3!B:I,8,0) -> 0811522178 | H4: =vlookup(B4,Sheet3!B:J,9,0) -> ningrumtia03@gmail.com | I4: SPB/SPG Toko | J4: =vlookup(B4,Sheet2!B:D,3,0) -> NUANSA PANGKALANBUN | K4: =vlookup(A4,Sheet2!A:E,5,0) -> KOTAWARINGIN BARAT | L4: =VLOOKUP(B4,Sheet3!B:L,11,0) -> 8585226544 | M4: =vlookup(B4,'data staffinc_3'!B:I,7,0) -> 45546 | N4: 46266 | O4: =vlookup(B4,'data staffinc_3'!B:I,8,0) -> 46265 | P4: =VLOOKUP(A4,Sheet2!A:F,6,0) -> BANJARMASIN | Q4: PT. Mahakarya Sukses Indonesia | R4: 70/30 | S4: 3910000 | T4: 2737000 | U4: 1173000 | W4: 3909005 | X4: 0 | Y4: =W4+X4 -> 3909005
A5: DM20260004 | B5: Agustina Galuh Prihaningtyas | C5: =vlookup(B5,Sheet3!B:C,2,0) -> Jl jagalan no 65 | D5: =vlookup(B5,Sheet3!B:D,3,0) -> 31634 | E5: =vlookup(B5,Sheet3!B:F,5,0) -> Yogyakarta | F5: =vlookup(B5,Sheet3!B:H,7,0) -> SLTA | G5: =vlookup(B5,Sheet3!B:I,8,0) -> 087814045446 | H5: =vlookup(B5,Sheet3!B:J,9,0) -> galuh8893@gmail.com | I5: SPB/SPG Toko | J5: =vlookup(B5,Sheet2!B:D,3,0) -> UFO YOGYAKARTA JOKTENG | K5: =vlookup(A5,Sheet2!A:E,5,0) -> YOGYAKARTA | L5: =VLOOKUP(B5,Sheet3!B:L,11,0) -> 1690194631 | M5: 45819 | N5: 46266 | O5: 46265 | P5: =VLOOKUP(A5,Sheet2!A:F,6,0) -> SEMARANG | Q5: PT. Mahakarya Sukses Indonesia | R5: 70/30 | S5: 2828000 | T5: 1979600 | U5: 848400 | W5: 2827593 | X5: 0 | Y5: =W5+X5 -> 2827593
A6: DM20260005 | B6: Ainun Jariah | C6: =vlookup(B6,Sheet3!B:C,2,0) -> Jl. Kelayan A | Gang Sidodadi RT.11 RW.01 No.18 | D6: =vlookup(B6,Sheet3!B:D,3,0) -> 34822 | E6: =vlookup(B6,Sheet3!B:F,5,0) -> Banjarmasin | F6: =vlookup(B6,Sheet3!B:H,7,0) -> SLTA | G6: =vlookup(B6,Sheet3!B:I,8,0) -> 0895608199789 | H6: =vlookup(B6,Sheet3!B:J,9,0) -> program.ainun@gmail.com | I6: SPB/SPG Toko | J6: =vlookup(B6,Sheet2!B:D,3,0) -> GOLDEN 10 | K6: =vlookup(A6,Sheet2!A:E,5,0) -> BANJARMASIN | L6: =VLOOKUP(B6,Sheet3!B:L,11,0) -> 7820819785 | M6: =vlookup(B6,'data staffinc_3'!B:I,7,0) -> 45685 | N6: 46266 | O6: =vlookup(B6,'data staffinc_3'!B:I,8,0) -> 46265 | P6: =VLOOKUP(A6,Sheet2!A:F,6,0) -> BANJARMASIN | Q6: PT. Mahakarya Sukses Indonesia | R6: 70/30 | S6: 3856000 | T6: 2699200 | U6: 1156800 | W6: 3855894 | X6: 0 | Y6: =W6+X6 -> 3855894
A7: DM20260006 | B7: Anggiza Gana Pawestri | C7: =vlookup(B7,Sheet3!B:C,2,0) -> Jl.Buni Malaka Rt06/08 no 15 kel.munjul kec. Cipayung Jakarta Timur | D7: =vlookup(B7,Sheet3!B:D,3,0) -> 31659 | E7: =vlookup(B7,Sheet3!B:F,5,0) -> Jakarta | F7: =vlookup(B7,Sheet3!B:H,7,0) -> SLTA | G7: =vlookup(B7,Sheet3!B:I,8,0) -> 087887345099 | H7: =vlookup(B7,Sheet3!B:J,9,0) -> Anggipawestri04@gmail.com | I7: SPB/SPG Toko | J7: =vlookup(B7,Sheet2!B:D,3,0) -> HARAPAN BARU | K7: JAKARTA | L7: =VLOOKUP(B7,Sheet3!B:L,11,0) -> 8691115984 | M7: 43409 | N7: 46266 | O7: 46265 | P7: =VLOOKUP(A7,Sheet2!A:F,6,0) -> JAKARTA | Q7: PT. Mahakarya Sukses Indonesia | R7: 70/30 | S7: 5730000 | T7: 4011000 | U7: 1719000 | W7: 5729876 | X7: 0 | Y7: =W7+X7 -> 5729876
A8: DM20260007 | B8: Anisa Nurajijah | C8: =vlookup(B8,Sheet3!B:C,2,0) -> jl.lingkar kota | D8: =vlookup(B8,Sheet3!B:D,3,0) -> 38319 | E8: =vlookup(B8,Sheet3!B:F,5,0) -> subang, jawa barat | F8: =vlookup(B8,Sheet3!B:H,7,0) -> SLTA | G8: =vlookup(B8,Sheet3!B:I,8,0) -> 089524367514 | H8: =vlookup(B8,Sheet3!B:J,9,0) -> uchanel1983@gmail.com | I8: SPB/SPG Toko | J8: =vlookup(B8,Sheet2!B:D,3,0) -> OSCAR GEMILANG | K8: =vlookup(A8,Sheet2!A:E,5,0) -> KETAPANG | M8: 45957 | N8: 46266 | O8: 46265 | P8: =VLOOKUP(A8,Sheet2!A:F,6,0) -> PONTIANAK | Q8: PT. Mahakarya Sukses Indonesia | R8: 70/30 | S8: 3562000 | T8: 2493400 | U8: 1068600 | W8: 3561801 | X8: 0 | Y8: =W8+X8 -> 3561801
A9: DM20260008 | B9: Annisa | C9: =vlookup(B9,Sheet3!B:C,2,0) -> Jl.keramat gg satu dua rt.10 no.37d kelurahan sungai bilu kecamatan banjarmasin timur banjarmasin 70236 | D9: =vlookup(B9,Sheet3!B:D,3,0) -> 33553 | E9: =vlookup(B9,Sheet3!B:F,5,0) -> Banjarmasin | F9: =vlookup(B9,Sheet3!B:H,7,0) -> SLTA | G9: =vlookup(B9,Sheet3!B:I,8,0) -> 085754771101 | H9: =vlookup(B9,Sheet3!B:J,9,0) -> Annisaauliani11@gmail.com | I9: SPB/SPG Toko | J9: =vlookup(B9,Sheet2!B:D,3,0) -> POS ELEKTRONIK | K9: =vlookup(A9,Sheet2!A:E,5,0) -> BANJARMASIN | L9: =VLOOKUP(B9,Sheet3!B:L,11,0) -> 0511915910 | M9: 42826 | N9: 46266 | O9: 46265 | P9: =VLOOKUP(A9,Sheet2!A:F,6,0) -> BANJARMASIN | Q9: PT. Mahakarya Sukses Indonesia | R9: 70/30 | S9: 3856000 | T9: 2699200 | U9: 1156800 | W9: 3855894 | X9: 0 | Y9: =W9+X9 -> 3855894
A10: DM20260009 | B10: Ardi Basri | C10: =vlookup(B10,Sheet3!B:C,2,0) -> Vila Mutiara Asri VII No.12 | D10: =vlookup(B10,Sheet3!B:D,3,0) -> 34283 | E10: =vlookup(B10,Sheet3!B:F,5,0) -> Makassar | F10: =vlookup(B10,Sheet3!B:H,7,0) -> S1 | G10: =vlookup(B10,Sheet3!B:I,8,0) -> 085756517715 | H10: =vlookup(B10,Sheet3!B:J,9,0) -> ardibasri948@gmail.com | I10: GTM | J10: =vlookup(B10,Sheet2!B:D,3,0) -> MAKASSAR | K10: =vlookup(A10,Sheet2!A:E,5,0) -> MAKASSAR | L10: =VLOOKUP(B10,Sheet3!B:L,11,0) -> 0251548799 | M10: =vlookup(B10,'data staffinc_3'!B:I,7,0) -> 46175 | N10: 46266 | O10: =vlookup(B10,'data staffinc_3'!B:I,8,0) -> 46265 | P10: =VLOOKUP(A10,Sheet2!A:F,6,0) -> MAKASSAR | Q10: PT. Mahakarya Sukses Indonesia | R10: Khusus | T10: 5128000 | W10: 4977815 | X10: 150000 | Y10: =W10+X10 -> 5127815
A11: DM20260010 | B11: Arenta putri Widyaningsih | C11: =vlookup(B11,Sheet3!B:C,2,0) -> Jl.margoyoso IV rt 6/4 | D11: =vlookup(B11,Sheet3!B:D,3,0) -> 38188 | E11: =vlookup(B11,Sheet3!B:F,5,0) -> Semarang | F11: =vlookup(B11,Sheet3!B:H,7,0) -> SLTA | G11: =vlookup(B11,Sheet3!B:I,8,0) -> 08973123823 | H11: =vlookup(B11,Sheet3!B:J,9,0) -> arentaputriwidyaningsih200704@gmail.com | I11: SPB/SPG Toko | J11: =vlookup(B11,Sheet2!B:D,3,0) -> ADA SILIWANGI | K11: =vlookup(A11,Sheet2!A:E,5,0) -> SEMARANG | L11: =VLOOKUP(B11,Sheet3!B:L,11,0) -> 8715675648 | M11: 46146 | N11: 46266 | O11: 46265 | P11: =VLOOKUP(A11,Sheet2!A:F,6,0) -> SEMARANG | Q11: PT. Mahakarya Sukses Indonesia | R11: 70/30 | S11: 3702000 | T11: 2591400 | U11: 1110600 | W11: 3701709 | X11: 0 | Y11: =W11+X11 -> 3701709
A12: DM20260011 | B12: Ari Kusumawati | C12: =vlookup(B12,Sheet3!B:C,2,0) -> Jl.Gunung Sahari 9 RT.005 RW.004 Kel.Gunung Sahari Utara, kec.Sawah besar, Jakarta pusat | D12: =vlookup(B12,Sheet3!B:D,3,0) -> 32778 | E12: =vlookup(B12,Sheet3!B:F,5,0) -> Jakarta | F12: =vlookup(B12,Sheet3!B:H,7,0) -> SLTA | G12: =vlookup(B12,Sheet3!B:I,8,0) -> 085780008440 | H12: =vlookup(B12,Sheet3!B:J,9,0) -> nayarengganis25@gmail.com | I12: SPB/SPG Outlet | J12: =vlookup(B12,Sheet2!B:D,3,0) -> MALL KELAPA GADING | K12: =vlookup(A12,Sheet2!A:E,5,0) -> JAKARTA | L12: =VLOOKUP(B12,Sheet3!B:L,11,0) -> 6840428964 | M12: 44844 | N12: 46266 | O12: 46265 | P12: =VLOOKUP(A12,Sheet2!A:F,6,0) -> JAKARTA | Q12: PT. Mahakarya Sukses Indonesia | R12: Khusus | S12: 5730000 | T12: 5730000 | W12: 5729876 | X12: 600000 | Y12: =W12+X12 -> 6329876
A13: DM20260012 | B13: Ayu Novitaningsih | C13: =vlookup(B13,Sheet3!B:C,2,0) -> Dusun bringin RT02 RW01 Desa Karangwaluh kecamatan Sampung Kabupaten Ponorogo | D13: =vlookup(B13,Sheet3!B:D,3,0) -> 35012 | E13: =vlookup(B13,Sheet3!B:F,5,0) -> Ponorogo | F13: =vlookup(B13,Sheet3!B:H,7,0) -> SLTA | G13: =vlookup(B13,Sheet3!B:I,8,0) -> 082141638390 | H13: =vlookup(B13,Sheet3!B:J,9,0) -> ayumamay09@gmail.com | I13: SPB/SPG Toko | J13: =vlookup(B13,Sheet2!B:D,3,0) -> CV SAMI JAYA | K13: =vlookup(A13,Sheet2!A:E,5,0) -> PONOROGO | L13: =VLOOKUP(B13,Sheet3!B:L,11,0) -> 2891046822 | M13: 46015 | N13: 46266 | O13: 46265 | P13: =VLOOKUP(A13,Sheet2!A:F,6,0) -> SURABAYA | Q13: PT. Mahakarya Sukses Indonesia | R13: 70/30 | S13: 2550000 | T13: 1785000 | U13: 765000 | W13: 2549876 | X13: 0 | Y13: =W13+X13 -> 2549876
A14: DM20260013 | B14: Bagus Dwi Ardiansyah | C14: =vlookup(B14,Sheet3!B:C,2,0) -> PONDOK BENOWO INDAH BO 14 SURABAYA | D14: =vlookup(B14,Sheet3!B:D,3,0) -> 35663 | E14: =vlookup(B14,Sheet3!B:F,5,0) -> SURABAYA | F14: =vlookup(B14,Sheet3!B:H,7,0) -> S1 | G14: =vlookup(B14,Sheet3!B:I,8,0) -> 081283148912 | H14: =vlookup(B14,Sheet3!B:J,9,0) -> bagusdwiar@gmail.com | I14: SPB/SPG MT | J14: =vlookup(B14,Sheet2!B:D,3,0) -> HARTONO BUKIT DARMO | K14: =vlookup(A14,Sheet2!A:E,5,0) -> SURABAYA | L14: =VLOOKUP(B14,Sheet3!B:L,11,0) -> 2582405442 | M14: 46047 | N14: 46266 | O14: 46265 | P14: =VLOOKUP(A14,Sheet2!A:F,6,0) -> SURABAYA | Q14: PT. Mahakarya Sukses Indonesia | R14: Khusus | S14: 5289000 | T14: 5289000 | W14: 5288796 | X14: 0 | Y14: =W14+X14 -> 5288796
A15: DM20260014 | B15: Balqis Ayudia Pramesti | C15: =vlookup(B15,Sheet3!B:C,2,0) -> pandak rt 04 rw 02 jatipandak sambeng | D15: =vlookup(B15,Sheet3!B:D,3,0) -> 38044 | E15: =vlookup(B15,Sheet3!B:F,5,0) -> sidoarjo | F15: =vlookup(B15,Sheet3!B:H,7,0) -> SLTA | G15: =vlookup(B15,Sheet3!B:I,8,0) -> 089514649794 | H15: =vlookup(B15,Sheet3!B:J,9,0) -> balqisayudia123@gmail.com | I15: SPB/SPG MT | J15: =vlookup(B15,Sheet2!B:D,3,0) -> HARTONO BUKIT DARMO | K15: =vlookup(A15,Sheet2!A:E,5,0) -> SURABAYA | L15: =VLOOKUP(B15,Sheet3!B:L,11,0) -> 5065480881 | P15: =VLOOKUP(A15,Sheet2!A:F,6,0) -> SURABAYA | Q15: PT. Stein Perkasa Internasional | R15: Khusus | S15: 5289000 | T15: 5289000
A16: DM20260015 | B16: Chamida Ananda Septiani | C16: =vlookup(B16,Sheet3!B:C,2,0) -> Dusun 1 Kasimbar Tengah Desa Kasimbar Kecamatan Kasimbar | D16: =vlookup(B16,Sheet3!B:D,3,0) -> 36429 | E16: =vlookup(B16,Sheet3!B:F,5,0) -> Parigi | F16: =vlookup(B16,Sheet3!B:H,7,0) -> SLTA | G16: =vlookup(B16,Sheet3!B:I,8,0) -> 085298512206 | H16: =vlookup(B16,Sheet3!B:J,9,0) -> chamidaananda@gmail.com | I16: SPB/SPG Toko | J16: =vlookup(B16,Sheet2!B:D,3,0) -> SMART KITCHEN | K16: =vlookup(A16,Sheet2!A:E,5,0) -> PALU | M16: 46240 | N16: 46266 | O16: 46265 | P16: =VLOOKUP(A16,Sheet2!A:F,6,0) -> MAKASSAR | Q16: PT. Mahakarya Sukses Indonesia | R16: 70/30 | S16: 4149000 | T16: 2904300 | U16: 1244700 | W16: 4148179 | X16: 0 | Y16: =W16+X16 -> 4148179
A17: DM20260016 | B17: Charles Setiawan | C17: =vlookup(B17,Sheet3!B:C,2,0) -> DUSUN TERATAI INDAH | D17: =vlookup(B17,Sheet3!B:D,3,0) -> 34794 | E17: =vlookup(B17,Sheet3!B:F,5,0) -> KETAPANG | F17: =vlookup(B17,Sheet3!B:H,7,0) -> SLTA | G17: =vlookup(B17,Sheet3!B:I,8,0) -> 085651034052 | H17: =vlookup(B17,Sheet3!B:J,9,0) -> cs5657394@gmail.com | I17: SPB/SPG Toko | J17: =vlookup(B17,Sheet2!B:D,3,0) -> TOKO PUTRA ELEKTRONIK | K17: =vlookup(A17,Sheet2!A:E,5,0) -> PONTIANAK | L17: =VLOOKUP(B17,Sheet3!B:L,11,0) -> 1711654599 | M17: 45845 | N17: 46266 | O17: 46265 | P17: =VLOOKUP(A17,Sheet2!A:F,6,0) -> PONTIANAK | Q17: PT. Mahakarya Sukses Indonesia | R17: 70/30 | S17: 3206000 | T17: 2244200 | U17: 961800 | W17: 3205220 | X17: 0 | Y17: =W17+X17 -> 3205220
A18: DM20260017 | B18: Christiana Dwi Jayanti | C18: =vlookup(B18,Sheet3!B:C,2,0) -> KARANGPUTIH TLOGO PRAMBANAN KLATEN RT 009 RW 006 | D18: =vlookup(B18,Sheet3!B:D,3,0) -> 35980 | E18: =vlookup(B18,Sheet3!B:F,5,0) -> KLATEN | F18: =vlookup(B18,Sheet3!B:H,7,0) -> SLTA | G18: =vlookup(B18,Sheet3!B:I,8,0) -> 085174367440 | H18: =vlookup(B18,Sheet3!B:J,9,0) -> christianadwijayanti78@gmail.com | I18: SPB/SPG Toko | J18: =vlookup(B18,Sheet2!B:D,3,0) -> A TAKRIB LIFE STYLE | K18: =vlookup(A18,Sheet2!A:E,5,0) -> YOGYAKARTA | L18: =VLOOKUP(B18,Sheet3!B:L,11,0) -> 0601290102 | M18: 45627 | N18: 46266 | O18: 46265 | P18: =VLOOKUP(A18,Sheet2!A:F,6,0) -> SEMARANG | Q18: PT. Mahakarya Sukses Indonesia | R18: 70/30 | S18: 2828000 | T18: 1979600 | U18: 848400 | W18: 2827593 | X18: 0 | Y18: =W18+X18 -> 2827593
A19: DM20260018 | B19: Darussalam | C19: =vlookup(B19,Sheet3!B:C,2,0) -> Dsn Dendelu. kel Tarobok. kec baebubta . luwu utara | D19: =vlookup(B19,Sheet3!B:D,3,0) -> 34354 | E19: =vlookup(B19,Sheet3!B:F,5,0) -> luwu utara | F19: =vlookup(B19,Sheet3!B:H,7,0) -> SLTA | G19: =vlookup(B19,Sheet3!B:I,8,0) -> 089501607968 | H19: =vlookup(B19,Sheet3!B:J,9,0) -> salamdarulmito26@gmail.com | I19: SPB/SPG Toko | J19: =vlookup(B19,Sheet2!B:D,3,0) -> GRAND TOSERBA PENGAYOMAN | K19: =vlookup(A19,Sheet2!A:E,5,0) -> MAKASSAR | L19: =VLOOKUP(B19,Sheet3!B:L,11,0) -> 7990187805 | M19: 45803 | N19: 46266 | O19: 46265 | P19: =VLOOKUP(A19,Sheet2!A:F,6,0) -> MAKASSAR | Q19: PT. Mahakarya Sukses Indonesia | R19: 70/30 | S19: 4149000 | T19: 2904300 | U19: 1244700 | W19: 4148179 | X19: 0 | Y19: =W19+X19 -> 4148179
A20: DM20260019 | B20: Deni Lindiansah | C20: =vlookup(B20,Sheet3!B:C,2,0) -> Jln Panyandaan rt 3 rw 07 Kel mandalamekar Kec Cimenyan Kab Bandung | D20: =vlookup(B20,Sheet3!B:D,3,0) -> 36862 | E20: =vlookup(B20,Sheet3!B:F,5,0) -> Bandung | F20: =vlookup(B20,Sheet3!B:H,7,0) -> SLTA | G20: =vlookup(B20,Sheet3!B:I,8,0) -> 089670444004 | H20: =vlookup(B20,Sheet3!B:J,9,0) -> denilnndsh@gmail.com | I20: SPB/SPG MT | J20: =vlookup(B20,Sheet2!B:D,3,0) -> HARTONO BANDUNG | K20: =vlookup(A20,Sheet2!A:E,5,0) -> BANDUNG | L20: =VLOOKUP(B20,Sheet3!B:L,11,0) -> 2832076288 | M20: 46036 | N20: 46266 | O20: 46265 | P20: =VLOOKUP(A20,Sheet2!A:F,6,0) -> BANDUNG | Q20: PT. Mahakarya Sukses Indonesia | R20: Khusus | S20: 4738000 | T20: 4738000 | W20: 4737678 | X20: 0 | Y20: =W20+X20 -> 4737678
A21: DM20260020 | B21: Devi Eriyanti | C21: =vlookup(B21,Sheet3!B:C,2,0) -> Jl Moh Roem | D21: =vlookup(B21,Sheet3!B:D,3,0) -> 34969 | E21: =vlookup(B21,Sheet3!B:F,5,0) -> Bontang | F21: =vlookup(B21,Sheet3!B:H,7,0) -> SLTA | G21: =vlookup(B21,Sheet3!B:I,8,0) -> 08135054923 | H21: =vlookup(B21,Sheet3!B:J,9,0) -> Vira08359@gmail.com | I21: SPB/SPG Toko | J21: =vlookup(B21,Sheet2!B:D,3,0) -> PONDOK ELEKTRONIK BANJARBARU | K21: =vlookup(A21,Sheet2!A:E,5,0) -> BANJARMASIN | L21: =VLOOKUP(B21,Sheet3!B:L,11,0) -> 6705117156 | M21: 46008 | N21: 46266 | O21: 46265 | P21: =VLOOKUP(A21,Sheet2!A:F,6,0) -> BANJARMASIN | Q21: PT. Mahakarya Sukses Indonesia | R21: 70/30 | S21: 3856000 | T21: 2699200 | U21: 1156800 | W21: 3843037 | X21: 0 | Y21: =W21+X21 -> 3843037
A22: DM20260021 | B22: Devi Isvaradilla Agrully | C22: =vlookup(B22,Sheet3!B:C,2,0) -> Jl MINANGKABAU NO 101 RT 04 BATU AMPAR | D22: =vlookup(B22,Sheet3!B:D,3,0) -> 37134 | E22: =vlookup(B22,Sheet3!B:F,5,0) -> Balikpapan | F22: =vlookup(B22,Sheet3!B:H,7,0) -> SLTA | G22: =vlookup(B22,Sheet3!B:I,8,0) -> 085656950939 | H22: =vlookup(B22,Sheet3!B:J,9,0) -> deviisvaradilla16@gmail.com | I22: SPB/SPG Toko | J22: =vlookup(B22,Sheet2!B:D,3,0) -> NUANSA BALIKPAPAN | K22: =vlookup(A22,Sheet2!A:E,5,0) -> BALIKPAPAN | L22: =VLOOKUP(B22,Sheet3!B:L,11,0) -> 7810287131 | M22: 45824 | N22: 46266 | O22: 46265 | P22: =VLOOKUP(A22,Sheet2!A:F,6,0) -> SAMARINDA | Q22: PT. Mahakarya Sukses Indonesia | R22: 70/30 | S22: 3857000 | T22: 2699900 | U22: 1157100 | W22: 3856694 | X22: 0 | Y22: =W22+X22 -> 3856694
A23: DM20260022 | B23: Dewi Pramudita | C23: =vlookup(B23,Sheet3!B:C,2,0) -> PALEMBANG, PLAJU | D23: =vlookup(B23,Sheet3!B:D,3,0) -> 39415 | E23: =vlookup(B23,Sheet3!B:F,5,0) -> Palembang | F23: =vlookup(B23,Sheet3!B:H,7,0) -> SLTA | G23: =vlookup(B23,Sheet3!B:I,8,0) -> 0895320866466 | H23: =vlookup(B23,Sheet3!B:J,9,0) -> pramudithadewi62@gmail.com | I23: SPB/SPG Toko | J23: =vlookup(B23,Sheet2!B:D,3,0) -> DAPOER MUTIARA (CV PELITA MAS) | K23: =vlookup(A23,Sheet2!A:E,5,0) -> PALEMBANG | L23: =VLOOKUP(B23,Sheet3!B:L,11,0) -> 1160615202 | M23: 46256 | N23: 46266 | O23: 46265 | P23: =VLOOKUP(A23,Sheet2!A:F,6,0) -> PALEMBANG | Q23: PT. Mahakarya Sukses Indonesia | R23: 70/30 | S23: 4193000 | T23: 2935100 | U23: 1257900 | W23: 4192837 | X23: 0 | Y23: =W23+X23 -> 4192837
A24: DM20260023 | B24: Diah Catur Apriani | C24: =vlookup(B24,Sheet3!B:C,2,0) -> Grecol, rt1 rw3 Kalimanah Kab purbalingga | D24: =vlookup(B24,Sheet3!B:D,3,0) -> 34432 | E24: =vlookup(B24,Sheet3!B:F,5,0) -> Banyumas | F24: =vlookup(B24,Sheet3!B:H,7,0) -> SLTA | G24: =vlookup(B24,Sheet3!B:I,8,0) -> 081568400117 | H24: =vlookup(B24,Sheet3!B:J,9,0) -> caturdiah95@gmail.com | I24: SPB/SPG Toko | J24: =vlookup(B24,Sheet2!B:D,3,0) -> DEPO PELITA | K24: SEMARANG | L24: =VLOOKUP(B24,Sheet3!B:L,11,0) -> 3581118790 | M24: 45714 | N24: 46266 | O24: 46265 | P24: =VLOOKUP(A24,Sheet2!A:F,6,0) -> SEMARANG | Q24: PT. Mahakarya Sukses Indonesia | R24: 70/30 | S24: 3702000 | T24: 2591400 | U24: 1110600 | W24: 2474598 | X24: 0 | Y24: =W24+X24 -> 2474598
A25: DM20260024 | B25: Dimas Setya Nugraha | C25: =vlookup(B25,Sheet3!B:C,2,0) -> Dusun Ngabeyan, Desa Nguwet, RT/Rw 002/002 Kecamatan Kranggan, Kabupaten Temanggung | D25: =vlookup(B25,Sheet3!B:D,3,0) -> 37094 | E25: =vlookup(B25,Sheet3!B:F,5,0) -> Temanggung | F25: =vlookup(B25,Sheet3!B:H,7,0) -> S1 | G25: =vlookup(B25,Sheet3!B:I,8,0) -> 085713753192 | H25: =vlookup(B25,Sheet3!B:J,9,0) -> setyadimas021@gmail.com | I25: SPB/SPG Toko | J25: =vlookup(B25,Sheet2!B:D,3,0) -> CANDI ELEKTRONIK | K25: =vlookup(A25,Sheet2!A:E,5,0) -> SUKOHARJO | L25: 1541007488 | P25: =VLOOKUP(A25,Sheet2!A:F,6,0) -> SEMARANG | Q25: PT. Mahakarya Sukses Indonesia | R25: 70/30 | S25: 2500000 | T25: 1750000 | U25: 750000
A26: DM20260025 | B26: Dinda Sri Rahayu | C26: =vlookup(B26,Sheet3!B:C,2,0) -> kp. pangsor rt.08/10 sukamantri, paseh | D26: =vlookup(B26,Sheet3!B:D,3,0) -> 36483 | E26: =vlookup(B26,Sheet3!B:F,5,0) -> Bandung | F26: =vlookup(B26,Sheet3!B:H,7,0) -> SLTA | G26: =vlookup(B26,Sheet3!B:I,8,0) -> 089659753361 | H26: =vlookup(B26,Sheet3!B:J,9,0) -> dindasrirahayu9@gmail.com | I26: SPB/SPG Toko | J26: =vlookup(B26,Sheet2!B:D,3,0) -> LOGIN MEGASTORE (ABC) | K26: =vlookup(A26,Sheet2!A:E,5,0) -> BANDUNG | L26: =VLOOKUP(B26,Sheet3!B:L,11,0) -> 3760618135 | M26: 45576 | N26: 46266 | O26: 46265 | P26: =VLOOKUP(A26,Sheet2!A:F,6,0) -> BANDUNG | Q26: PT. Mahakarya Sukses Indonesia | R26: 70/30 | S26: 4738000 | T26: 3316600 | U26: 1421400 | W26: 4737678 | X26: 0 | Y26: =W26+X26 -> 4737678
A27: DM20260026 | B27: Ela Siska Ariatun | C27: =vlookup(B27,Sheet3!B:C,2,0) -> JLN. MODANG GG.RUKUN | D27: =vlookup(B27,Sheet3!B:D,3,0) -> 37477 | E27: =vlookup(B27,Sheet3!B:F,5,0) -> MOJOKERTO | F27: =vlookup(B27,Sheet3!B:H,7,0) -> SLTA | G27: =vlookup(B27,Sheet3!B:I,8,0) -> 082358812078 | H27: =vlookup(B27,Sheet3!B:J,9,0) -> elasiska01@gmail.com | I27: SPB/SPG Toko | J27: =vlookup(B27,Sheet2!B:D,3,0) -> NUANSA ELEKTRONIC TANAH GROGOT | K27: =vlookup(A27,Sheet2!A:E,5,0) -> PASER | L27: =VLOOKUP(B27,Sheet3!B:L,11,0) -> 7815831241 | M27: 45647 | N27: 46266 | O27: 46265 | P27: =VLOOKUP(A27,Sheet2!A:F,6,0) -> SAMARINDA | Q27: PT. Mahakarya Sukses Indonesia | R27: 70/30 | S27: 3777000 | T27: 2643900 | U27: 1133100 | W27: 3776998 | X27: 0 | Y27: =W27+X27 -> 3776998
A28: DM20260027 | B28: Elisa Putra Afdiono | C28: =vlookup(B28,Sheet3!B:C,2,0) -> Margorejo 2G nomer 32 | D28: =vlookup(B28,Sheet3!B:D,3,0) -> 35132 | E28: =vlookup(B28,Sheet3!B:F,5,0) -> Surabaya | F28: =vlookup(B28,Sheet3!B:H,7,0) -> SLTA | G28: =vlookup(B28,Sheet3!B:I,8,0) -> 089686949505 | H28: =vlookup(B28,Sheet3!B:J,9,0) -> zolla041123@gmail.com | I28: SPB/SPG Toko | J28: =vlookup(B28,Sheet2!B:D,3,0) -> TOENG MARKET JAKSA AGUNG SUPRAPTO | K28: =vlookup(A28,Sheet2!A:E,5,0) -> SURABAYA | L28: =VLOOKUP(B28,Sheet3!B:L,11,0) -> 5600289308 | M28: 44077 | N28: 46266 | O28: 46265 | P28: =VLOOKUP(A28,Sheet2!A:F,6,0) -> SURABAYA | Q28: PT. Mahakarya Sukses Indonesia | R28: 70/30 | S28: 5289000 | T28: 3702300 | U28: 1586700 | W28: 5288796 | X28: 0 | Y28: =W28+X28 -> 5288796
A29: DM20260028 | B29: Elisabeth Noviyanti Ayu N | C29: =vlookup(B29,Sheet3!B:C,2,0) -> Dusun Meno, rt003/rw004 Desa Rhee Loka Kecamatan Rhee Kabupaten Sumbawa | D29: =vlookup(B29,Sheet3!B:D,3,0) -> 35751 | E29: =vlookup(B29,Sheet3!B:F,5,0) -> Sumbawa | F29: =vlookup(B29,Sheet3!B:H,7,0) -> S1 | G29: =vlookup(B29,Sheet3!B:I,8,0) -> 087865850309 | H29: =vlookup(B29,Sheet3!B:J,9,0) -> elisabethayu1997@gmail.com | I29: SPB/SPG Toko | J29: =vlookup(B29,Sheet2!B:D,3,0) -> TOKO JAYA KITCHEN LOMBOK | K29: =vlookup(A29,Sheet2!A:E,5,0) -> MATARAM | L29: =VLOOKUP(B29,Sheet3!B:L,11,0) -> 0562190331 | M29: =vlookup(B29,'data staffinc_3'!B:I,7,0) -> 45920 | N29: 46266 | O29: =vlookup(B29,'data staffinc_3'!B:I,8,0) -> 46265 | P29: =VLOOKUP(A29,Sheet2!A:F,6,0) -> SURABAYA | Q29: PT. Mahakarya Sukses Indonesia | R29: Khusus | T29: 3020000 | W29: 3019015 | X29: 0 | Y29: =W29+X29 -> 3019015
A30: DM20260029 | B30: Eza Adela | C30: =vlookup(B30,Sheet3!B:C,2,0) -> Dusun Danau Kuala Selakau | D30: =vlookup(B30,Sheet3!B:D,3,0) -> 37747 | E30: =vlookup(B30,Sheet3!B:F,5,0) -> Selakau , Kalimantan barat Kabupaten Sambas | F30: =vlookup(B30,Sheet3!B:H,7,0) -> SLTA | G30: =vlookup(B30,Sheet3!B:I,8,0) -> 085656271235 | H30: =vlookup(B30,Sheet3!B:J,9,0) -> adelaeza021@gmail.com | I30: SPB/SPG Toko | J30: =vlookup(B30,Sheet2!B:D,3,0) -> HIBURAN BARU SINGKAWANG | K30: =vlookup(A30,Sheet2!A:E,5,0) -> PONTIANAK | L30: =VLOOKUP(B30,Sheet3!B:L,11,0) -> 8171876893 | M30: 46119 | N30: 46266 | O30: 46265 | P30: =VLOOKUP(A30,Sheet2!A:F,6,0) -> PONTIANAK | Q30: PT. Mahakarya Sukses Indonesia | R30: 70/30 | S30: 3248000 | T30: 2273600 | U30: 974400 | W30: 3247387 | X30: 0 | Y30: =W30+X30 -> 3247387
A31: DM20260030 | B31: Fadhila Rahmatika Haya | C31: =vlookup(B31,Sheet3!B:C,2,0) -> Sangkrah RT 2 RW 11 kelurahan Sangkrah kecamatan pasar Kliwon Surakarta Jawa tengah | D31: =vlookup(B31,Sheet3!B:D,3,0) -> 36788 | E31: =vlookup(B31,Sheet3!B:F,5,0) -> Surakarta | F31: =vlookup(B31,Sheet3!B:H,7,0) -> SLTA | G31: =vlookup(B31,Sheet3!B:I,8,0) -> 085725663034 | H31: =vlookup(B31,Sheet3!B:J,9,0) -> fadhilaarh19@gmail.com | I31: SPB/SPG Toko | J31: =vlookup(B31,Sheet2!B:D,3,0) -> CANDI ELEKTRONIC 310 | K31: =vlookup(A31,Sheet2!A:E,5,0) -> SEMARANG | L31: =VLOOKUP(B31,Sheet3!B:L,11,0) -> 1530616408 | P31: =VLOOKUP(A31,Sheet2!A:F,6,0) -> SEMARANG | Q31: PT. Mahakarya Sukses Indonesia | R31: 70/30 | S31: 3702000 | T31: 2591400 | U31: 1110600
A32: DM20260031 | B32: Fahrur Reza | C32: =vlookup(B32,Sheet3!B:C,2,0) -> Kalibata Selatan no 41, RT 002 RW 009 Kelurahan Kalibata Kecamatan Pancoran Jakarta Selatan 12740 | D32: =vlookup(B32,Sheet3!B:D,3,0) -> 34895 | E32: =vlookup(B32,Sheet3!B:F,5,0) -> Jakarta | F32: =vlookup(B32,Sheet3!B:H,7,0) -> S1 | G32: =vlookup(B32,Sheet3!B:I,8,0) -> 087851843056 | H32: =vlookup(B32,Sheet3!B:J,9,0) -> ezaenii@gmail.com | I32: SPB/SPG Toko | J32: =vlookup(B32,Sheet2!B:D,3,0) -> SPN HOUSEWARE | K32: =vlookup(A32,Sheet2!A:E,5,0) -> JAKARTA | L32: =VLOOKUP(B32,Sheet3!B:L,11,0) -> 1280346540 | M32: 45712 | N32: 46266 | O32: 46265 | P32: =VLOOKUP(A32,Sheet2!A:F,6,0) -> JAKARTA | Q32: PT. Mahakarya Sukses Indonesia | R32: 70/30 | S32: 5730000 | T32: 4011000 | U32: 1719000 | W32: 5729876 | X32: 0 | Y32: =W32+X32 -> 5729876
A33: DM20260032 | B33: Faisol Adha | C33: =vlookup(B33,Sheet3!B:C,2,0) -> DSN. PULE UTARA RT:002/RW:001 PULE, KANDAT | D33: =vlookup(B33,Sheet3!B:D,3,0) -> 34597 | E33: =vlookup(B33,Sheet3!B:F,5,0) -> KEDIRI | F33: =vlookup(B33,Sheet3!B:H,7,0) -> SLTA | G33: =vlookup(B33,Sheet3!B:I,8,0) -> 085748348360 | H33: =vlookup(B33,Sheet3!B:J,9,0) -> faisol.adha03@gmail.com | I33: SPB/SPG Outlet | J33: =vlookup(B33,Sheet2!B:D,3,0) -> TUNJUNGAN PLAZA | K33: =vlookup(A33,Sheet2!A:E,5,0) -> SURABAYA | L33: =VLOOKUP(B33,Sheet3!B:L,11,0) -> 8220741924 | M33: 45147 | N33: 46266 | O33: 46265 | P33: =VLOOKUP(A33,Sheet2!A:F,6,0) -> SURABAYA | Q33: PT. Mahakarya Sukses Indonesia | R33: Khusus | S33: 5289000 | T33: 5289000 | W33: 5288796 | X33: 600000 | Y33: =W33+X33 -> 5888796
A34: DM20260033 | B34: Fatra Laily | C34: =vlookup(B34,Sheet3!B:C,2,0) -> Jln barukang 6 no 2 | D34: =vlookup(B34,Sheet3!B:D,3,0) -> 35910 | E34: =vlookup(B34,Sheet3!B:F,5,0) -> Makassar | F34: =vlookup(B34,Sheet3!B:H,7,0) -> S1 | G34: =vlookup(B34,Sheet3!B:I,8,0) -> 089684056159 | H34: =vlookup(B34,Sheet3!B:J,9,0) -> Fatralaily98@gmail.com | I34: SPB/SPG Toko | J34: =vlookup(B34,Sheet2!B:D,3,0) -> SEMERU SARAPPO | K34: =vlookup(A34,Sheet2!A:E,5,0) -> MAKASSAR | L34: =VLOOKUP(B34,Sheet3!B:L,11,0) -> 7685985489 | M34: 46128 | N34: 46266 | O34: 46265 | P34: =VLOOKUP(A34,Sheet2!A:F,6,0) -> MAKASSAR | Q34: PT. Mahakarya Sukses Indonesia | R34: 70/30 | S34: 4149000 | T34: 2904300 | U34: 1244700 | W34: 4148179 | X34: 0 | Y34: =W34+X34 -> 4148179
A35: DM20260034 | B35: Febry Valentino | C35: =vlookup(B35,Sheet3!B:C,2,0) -> Jl. Berlian, No.i04, Bontang lestari | D35: =vlookup(B35,Sheet3!B:D,3,0) -> 38030 | E35: =vlookup(B35,Sheet3!B:F,5,0) -> Bontang | F35: =vlookup(B35,Sheet3!B:H,7,0) -> SLTA | G35: =vlookup(B35,Sheet3!B:I,8,0) -> 081251882460 | H35: =vlookup(B35,Sheet3!B:J,9,0) -> febrivalentino24@gmail.com | I35: SPB/SPG Toko | J35: =vlookup(B35,Sheet2!B:D,3,0) -> NUANSA ELEKTRONIK BONTANG | K35: =vlookup(A35,Sheet2!A:E,5,0) -> BONTANG | L35: =VLOOKUP(B35,Sheet3!B:L,11,0) -> 6705379401 | M35: 45915 | N35: 46266 | O35: 46265 | P35: =VLOOKUP(A35,Sheet2!A:F,6,0) -> SAMARINDA | Q35: PT. Mahakarya Sukses Indonesia | R35: 70/30 | S35: 3800000 | T35: 2660000 | U35: 1140000 | W35: 3799480 | X35: 0 | Y35: =W35+X35 -> 3799480
A36: DM20260035 | B36: Ferdinand Anthonius Harianja | C36: =vlookup(B36,Sheet3!B:C,2,0) -> Dusun III Perum Johar II Jl. Semangka No.11 | D36: =vlookup(B36,Sheet3!B:D,3,0) -> 36422 | E36: =vlookup(B36,Sheet3!B:F,5,0) -> Payakumbuh | F36: =vlookup(B36,Sheet3!B:H,7,0) -> S1 | G36: =vlookup(B36,Sheet3!B:I,8,0) -> 089512709094 | H36: =vlookup(B36,Sheet3!B:J,9,0) -> ferdinandanthonius1@gmail.com | I36: =vlookup(A36,Sheet2!A:E,3,0) -> GTM | J36: =vlookup(B36,Sheet2!B:D,3,0) -> Kota Medan | K36: =vlookup(A36,Sheet2!A:E,5,0) -> MEDAN | L36: =VLOOKUP(B36,Sheet3!B:L,11,0) -> 2421392678 | M36: =vlookup(B36,'data staffinc_3'!B:I,7,0) -> 46174 | N36: 46266 | O36: =vlookup(B36,'data staffinc_3'!B:I,8,0) -> 46265 | P36: =VLOOKUP(A36,Sheet2!A:F,6,0) -> MEDAN | Q36: PT. Mahakarya Sukses Indonesia | R36: Khusus | T36: 5353000 | W36: 5202238 | X36: 150000 | Y36: =W36+X36 -> 5352238
A37: DM20260036 | B37: Ferdiyan | C37: =vlookup(B37,Sheet3!B:C,2,0) -> JL D.I PANJAITAN NO 08 RT 4 SUMBER REJO | D37: =vlookup(B37,Sheet3!B:D,3,0) -> 37670 | E37: =vlookup(B37,Sheet3!B:F,5,0) -> Balikpapan | F37: =vlookup(B37,Sheet3!B:H,7,0) -> SLTA | G37: =vlookup(B37,Sheet3!B:I,8,0) -> 087773201795 | H37: =vlookup(B37,Sheet3!B:J,9,0) -> Ferdiiiaaann@gmail.com | I37: SPB/SPG Toko | J37: =vlookup(B37,Sheet2!B:D,3,0) -> NUANSA BALIKPAPAN KILO | K37: =vlookup(A37,Sheet2!A:E,5,0) -> BALIKPAPAN | M37: 46202 | N37: 46266 | O37: 46265 | P37: =VLOOKUP(A37,Sheet2!A:F,6,0) -> SAMARINDA | Q37: PT. Mahakarya Sukses Indonesia | R37: 70/30 | S37: 3857000 | T37: 2699900 | U37: 1157100 | W37: 3856694 | X37: 0 | Y37: =W37+X37 -> 3856694
A38: DM20260037 | B38: Fiqri Nur Arfindiyani Putri | C38: =vlookup(B38,Sheet3!B:C,2,0) -> Bendo Rt07/Rw02 , Katur, Gayam Bojonegoro | D38: =vlookup(B38,Sheet3!B:D,3,0) -> 37614 | E38: =vlookup(B38,Sheet3!B:F,5,0) -> Surabaya | F38: =vlookup(B38,Sheet3!B:H,7,0) -> SLTA | G38: =vlookup(B38,Sheet3!B:I,8,0) -> 085604913433 | H38: =vlookup(B38,Sheet3!B:J,9,0) -> findyptr024@gmail.com | I38: SPB/SPG Toko | J38: =vlookup(B38,Sheet2!B:D,3,0) -> OGAN BANDULAN & OGAN BONDOWOSO | K38: =vlookup(A38,Sheet2!A:E,5,0) -> MALANG | M38: 46240 | N38: 46266 | O38: 46265 | P38: =VLOOKUP(A38,Sheet2!A:F,6,0) -> SURABAYA | Q38: PT. Mahakarya Sukses Indonesia | R38: 70/30 | S38: 3803000 | T38: 2662100 | U38: 1140900 | W38: 3736101 | X38: 0 | Y38: =W38+X38 -> 3736101
A39: DM20260038 | B39: Firanda | C39: =vlookup(B39,Sheet3!B:C,2,0) -> DUSUN IV DESA SUNGAI PINANG | D39: =vlookup(B39,Sheet3!B:D,3,0) -> 39056 | E39: =vlookup(B39,Sheet3!B:F,5,0) -> banyuasin | F39: =vlookup(B39,Sheet3!B:H,7,0) -> SLTA | G39: =vlookup(B39,Sheet3!B:I,8,0) -> 083872915839 | H39: =vlookup(B39,Sheet3!B:J,9,0) -> fanda5833@gmail.com | I39: SPB/SPG Toko | J39: =vlookup(B39,Sheet2!B:D,3,0) -> MDP SUPERSTORE | K39: =vlookup(A39,Sheet2!A:E,5,0) -> PALEMBANG | L39: =VLOOKUP(B39,Sheet3!B:L,11,0) -> 8435689139 | M39: 45567 | N39: 46266 | O39: 46265 | P39: =VLOOKUP(A39,Sheet2!A:F,6,0) -> PALEMBANG | Q39: PT. Mahakarya Sukses Indonesia | R39: 70/30 | S39: 4193000 | T39: 2935100 | U39: 1257900 | W39: 4192837 | X39: 0 | Y39: =W39+X39 -> 4192837
A40: DM20260039 | B40: Firda Duri Yatinal Ulya | C40: =vlookup(B40,Sheet3!B:C,2,0) -> JL.PEMUDA 2 GG.PENDAWA BLOK.E NO.86 RT.012 KEL.TEMINDUNG PERMAI KEC.SUNGAI PINANG | D40: =vlookup(B40,Sheet3!B:D,3,0) -> -659022 | E40: =vlookup(B40,Sheet3!B:F,5,0) -> SAMARINDA | F40: =vlookup(B40,Sheet3!B:H,7,0) -> SLTA | G40: =vlookup(B40,Sheet3!B:I,8,0) -> 082128843818 | H40: =vlookup(B40,Sheet3!B:J,9,0) -> firdaduriatinalulya@gmail.com | I40: SPB/SPG Toko | J40: =vlookup(B40,Sheet2!B:D,3,0) -> NUANSA IMAM BONJOL | K40: =vlookup(A40,Sheet2!A:E,5,0) -> SAMARINDA | L40: =VLOOKUP(B40,Sheet3!B:L,11,0) -> 7935297133 | M40: 43777 | N40: 46266 | O40: 46265 | P40: =VLOOKUP(A40,Sheet2!A:F,6,0) -> SAMARINDA | Q40: PT. Mahakarya Sukses Indonesia | R40: 70/30 | S40: 3984000 | T40: 2788800 | U40: 1195200 | V40: Resign per 20/9 | W40: 3983882 | X40: 0 | Y40: =W40+X40 -> 3983882
...

Sheet data staffinc_3
A1: No | B1: Mitra Sampingan's Name | C1: Position | D1: Area | E1: Branch Name | F1: Period | G1: Status | H1: Join Date | I1: Last Day (if inactive) | J1: Actual Working Days | K1: Effective Working Days | L1: Overtime Hours | M1: Basic Salary | N1: Tunjangan Outlet / Sales | O1: Upah Lembur/jam | P1: EWA | Q1: Adjustment (-) | R1: THP | S1: Notes Basic Salary | T1: Notes Overtime | U1: Notes Adjustment | V1: Note from Staffinc to MITO
A2: 1 | B2: Anggiza Gana Pawestri | C2: SPG/SPB Toko | D2: JABO | E2: JABO - HARAPAN BARU | F2: 25 Jul 2026 - 24 Aug 2026 | G2: inactive | H2: 43409 | I2: 46265 | J2: 28 | K2: 26 | M2: 5729876 | N2: 0 | O2: 15000 | P2: 660000 | R2: #VALUE! | S2: Hari Kerja: 28 / 26 x 5729876 | T2: Total jam lembur yang disetujui =
A3: 2 | B3: Annisa | C3: SPG/SPB Toko | D3: BANJARMASIN | E3: BANJARMASIN - POS ELEKTRONIK | F3: 25 Jul 2026 - 24 Aug 2026 | G3: inactive | H3: 42826 | I3: 46265 | J3: 30 | K3: 26 | M3: 3855894 | N3: 0 | O3: 15000 | R3: #VALUE! | S3: Hari Kerja: 30 / 26 x 3855894
A4: 3 | B4: Ilham Ansyar | C4: SPG/SPB Toko | D4: BANJARMASIN | E4: BANJARMASIN - POS ELEKTRONIK | F4: 25 Jul 2026 - 24 Aug 2026 | G4: inactive | H4: 42815 | I4: 46265 | J4: 30 | K4: 26 | M4: 3855894 | N4: 0 | O4: 15000 | P4: 1905000 | R4: 2579108 | S4: Hari Kerja: 30 / 26 x 3855894
A5: 4 | B5: Irma Fitriani | C5: SPG/SPB Toko | D5: MAKASSAR | E5: MAKASSAR - MAXI PERINTIS | F5: 25 Jul 2026 - 24 Aug 2026 | G5: inactive | H5: 43440 | I5: 46265 | J5: 27 | K5: 26 | M5: 4148179 | N5: 0 | O5: 15000 | R5: #VALUE! | S5: Hari Kerja: 27 / 26 x 4148179
A6: 5 | B6: Retno Dwi Ningrum | C6: SPG/SPB Toko | D6: PALEMBANG | E6: PALEMBANG - DAPOER MUTIARA (CV PELITA MAS) | F6: 25 Jul 2026 - 24 Aug 2026 | G6: inactive | H6: 42962 | I6: 46258 | J6: 27 | K6: 26 | M6: 4192837 | N6: 0 | O6: 15000 | R6: #VALUE! | S6: Hari Kerja: 27 / 26 x 4192837
A7: 6 | B7: Firda Duri Yatinal Ulya | C7: SPG/SPB Toko | D7: SAMARINDA | E7: SAMARINDA - NUANSA IMAM BONJOL | F7: 25 Jul 2026 - 24 Aug 2026 | G7: inactive | H7: 43777 | I7: 46265 | J7: 28 | K7: 26 | M7: 3983882 | N7: 0 | O7: 15000 | R7: #VALUE! | S7: Hari Kerja: 28 / 26 x 3983882
A8: 7 | B8: Mochamad Abdi Akbar | C8: SPG/SPB Toko | D8: SURABAYA | E8: SURABAYA - OGAN BANDULAN & OGAN BONDOWOSO | F8: 25 Jul 2026 - 24 Aug 2026 | G8: inactive | H8: 43374 | I8: 46265 | J8: 27 | K8: 26 | M8: 5288796 | N8: 0 | O8: 15000 | P8: 584097 | R8: 4943114 | S8: Hari Kerja: 27 / 26 x 5288796
A9: 8 | B9: Elisa Putra Afdiono | C9: SPG/SPB Toko | D9: SURABAYA | E9: SURABAYA - TOENG MARKET JAKSA AGUNG SUPRAPTO | F9: 25 Jul 2026 - 24 Aug 2026 | G9: inactive | H9: 44077 | I9: 46265 | J9: 27 | K9: 26 | M9: 5288796 | N9: 0 | O9: 15000 | P9: 1834500 | R9: 3692711 | S9: Hari Kerja: 27 / 26 x 5288796
A10: 9 | B10: I Ketut Sugiarta | C10: SPG/SPB Toko | D10: MAKASSAR | E10: MAKASSAR - STAR KITCHEN | F10: 25 Jul 2026 - 24 Aug 2026 | G10: inactive | H10: 44753 | I10: 46265 | J10: 26 | K10: 26 | M10: 4148179 | N10: 0 | O10: 15000 | R10: #VALUE! | S10: Hari Kerja: 26 / 26 x 4148179
A11: 10 | B11: Sri Astuti | C11: SPG/SPB Toko | D11: PEKANBARU | E11: PEKANBARU - GOLDEN DRAGON ELEKTRONIK | F11: 25 Jul 2026 - 24 Aug 2026 | G11: inactive | H11: 44816 | I11: 46265 | J11: 27 | K11: 26 | M11: 3998179 | N11: 0 | O11: 15000 | P11: 1943000 | R11: 2243955 | S11: Hari Kerja: 27 / 26 x 3998179
A12: 11 | B12: Adelina Astuti | C12: SPG/SPB Outlet | D12: OUTLET | E12: OUTLET - JABODETABEK - MALL KELAPA GADING | F12: 25 Jul 2026 - 24 Aug 2026 | G12: inactive | H12: 44852 | I12: 46265 | J12: 29 | K12: 26 | M12: 5729876 | N12: 600000 | O12: 15000 | R12: #VALUE! | S12: Hari Kerja: 29 / 26 x 5729876
A13: 12 | B13: Ari Kusumawati | C13: SPG/SPB Outlet | D13: OUTLET | E13: OUTLET - JABODETABEK - MALL KELAPA GADING | F13: 25 Jul 2026 - 24 Aug 2026 | G13: inactive | H13: 44844 | I13: 46265 | J13: 30 | K13: 26 | M13: 5729876 | N13: 600000 | O13: 15000 | R13: #VALUE! | S13: Hari Kerja: 30 / 26 x 5729876
A14: 13 | B14: Joko Supriatna | C14: SPG/SPB Outlet | D14: OUTLET | E14: OUTLET - JABODETABEK - MALL KELAPA GADING | F14: 25 Jul 2026 - 24 Aug 2026 | G14: inactive | H14: 44837 | I14: 46265 | J14: 28 | K14: 26 | M14: 5729876 | N14: 600000 | O14: 15000 | R14: #VALUE! | S14: Hari Kerja: 28 / 26 x 5729876
A15: 14 | B15: Firda Nur Agustin Cahyani | C15: SPG/SPB Toko | D15: BANDUNG | E15: BANDUNG - TOKO SINAR GUNTUR | F15: 25 Jul 2026 - 24 Aug 2026 | G15: inactive | H15: 44858 | I15: 46265 | J15: 28 | K15: 26 | M15: 2472227 | N15: 0 | O15: 15000 | R15: #VALUE! | S15: Hari Kerja: 28 / 26 x 2472227
A16: 15 | B16: Habib Mustopa | C16: SPG/SPB Toko | D16: SEMARANG | E16: SEMARANG - WIJAYA ELEKTRONIK | F16: 25 Jul 2026 - 24 Aug 2026 | G16: inactive | H16: 44911 | I16: 46265 | J16: 27 | K16: 26 | M16: 4233374 | N16: 0 | O16: 15000 | P16: 811500 | R16: 3619696 | S16: Hari Kerja: 27 / 26 x 4233374
A17: 16 | B17: Suci Ramadhani | C17: SPG/SPB Toko | D17: PEKANBARU | E17: PEKANBARU - BERKAT ELEKTRONIK | F17: 25 Jul 2026 - 24 Aug 2026 | G17: inactive | H17: 44963 | I17: 46265 | J17: 27 | K17: 26 | M17: 3898210 | N17: 0 | O17: 15000 | R17: #VALUE! | S17: Hari Kerja: 27 / 26 x 3898210
A18: 17 | B18: Nada Fadhillah Shobah | C18: SPG/SPB Toko | D18: MEDAN | E18: MEDAN - SH MART ELEKTRONIK | F18: 25 Jul 2026 - 24 Aug 2026 | G18: inactive | H18: 45054 | I18: 46265 | J18: 25 | K18: 26 | M18: 4335198 | N18: 0 | O18: 15000 | R18: #VALUE! | S18: Hari Kerja: 25 / 26 x 4335198
A19: 18 | B19: Paramita Restuningtyas | C19: SPG/SPB Toko | D19: SEMARANG | E19: SEMARANG - PIRANTI HOUSEWARE | F19: 25 Jul 2026 - 24 Aug 2026 | G19: inactive | H19: 45061 | I19: 46265 | J19: 27 | K19: 26 | M19: 3701709 | N19: 0 | O19: 15000 | R19: #VALUE! | S19: Hari Kerja: 27 / 26 x 3701709
A20: 19 | B20: Yuliana Siswanti | C20: SPG/SPB Outlet | D20: OUTLET | E20: OUTLET - SURABAYA - TUNJUNGAN PLAZA | F20: 25 Jul 2026 - 24 Aug 2026 | G20: inactive | H20: 45147 | I20: 46265 | J20: 26 | K20: 26 | M20: 5288796 | N20: 600000 | O20: 15000 | R20: #VALUE! | S20: Hari Kerja: 26 / 26 x 5288796
A21: 20 | B21: Faisol Adha | C21: SPG/SPB Outlet | D21: OUTLET | E21: OUTLET - SURABAYA - TUNJUNGAN PLAZA | F21: 25 Jul 2026 - 24 Aug 2026 | G21: inactive | H21: 45147 | I21: 46265 | J21: 27 | K21: 26 | M21: 5288796 | N21: 600000 | O21: 15000 | R21: #VALUE! | S21: Hari Kerja: 27 / 26 x 5288796
A22: 21 | B22: Muhammad Hafrizal | C22: SPG/SPB Outlet | D22: OUTLET | E22: OUTLET - SURABAYA - TUNJUNGAN PLAZA | F22: 25 Jul 2026 - 24 Aug 2026 | G22: inactive | H22: 45152 | I22: 46265 | J22: 27 | K22: 26 | M22: 5288796 | N22: 600000 | O22: 15000 | R22: #VALUE! | S22: Hari Kerja: 27 / 26 x 5288796
A23: 22 | B23: Fitri Wulandari | C23: SPG/SPB Toko | D23: BANJARMASIN | E23: BANJARMASIN - PONDOK ELEKTRONIK | F23: 25 Jul 2026 - 24 Aug 2026 | G23: inactive | H23: 45323 | I23: 46265 | J23: 25 | K23: 26 | M23: 3855894 | N23: 0 | O23: 15000 | R23: #VALUE! | S23: Hari Kerja: 25 / 26 x 3855894
A24: 23 | B24: Hendrika Buwa | C24: SPG/SPB Toko | D24: SAMARINDA | E24: SAMARINDA - MAMASUKA | F24: 25 Jul 2026 - 24 Aug 2026 | G24: inactive | H24: 45327 | I24: 46259 | J24: 26 | K24: 26 | M24: 3983882 | N24: 0 | O24: 15000 | P24: 750000 | R24: 3268882 | S24: Hari Kerja: 26 / 26 x 3983882
A25: 24 | B25: Sulaiman | C25: SPG/SPB Toko | D25: MAKASSAR | E25: MAKASSAR - SEMERU PERINTIS | F25: 25 Jul 2026 - 24 Aug 2026 | G25: inactive | H25: 45356 | I25: 46265 | J25: 28 | K25: 26 | M25: 4148179 | N25: 0 | O25: 15000 | R25: #VALUE! | S25: Hari Kerja: 28 / 26 x 4148179
A26: 25 | B26: Putri Ananda | C26: SPG/SPB Toko | D26: MEDAN | E26: MEDAN - WIEGO HOUSEWARE TRITURA | F26: 25 Jul 2026 - 24 Aug 2026 | G26: inactive | H26: 45352 | I26: 46265 | J26: 22 | K26: 26 | M26: 4335198 | N26: 0 | O26: 15000 | R26: #VALUE! | S26: Hari Kerja: 22 / 26 x 4335198
A27: 26 | B27: Nurmalita Widiyanti | C27: SPG/SPB Toko | D27: SURABAYA | E27: SURABAYA - CV OMEGA SEJAHTERA | F27: 25 Jul 2026 - 24 Aug 2026 | G27: inactive | H27: 45446 | I27: 46265 | J27: 27 | K27: 26 | M27: 2628190 | N27: 0 | O27: 15000 | R27: #VALUE! | S27: Hari Kerja: 27 / 26 x 2628190
A28: 27 | B28: Rindiani Herdialova | C28: SPG/SPB Toko | D28: PADANG | E28: PADANG - A FAUZI | F28: 25 Jul 2026 - 24 Aug 2026 | G28: inactive | H28: 45474 | I28: 46265 | J28: 25 | K28: 26 | M28: 3182955 | N28: 0 | O28: 15000 | R28: #VALUE! | S28: Hari Kerja: 25 / 26 x 3182955
A29: 28 | B29: Nany Maria Panjaitan | C29: SPG/SPB Toko | D29: SURABAYA | E29: SURABAYA - PERDANA MANYAR | F29: 25 Jul 2026 - 24 Aug 2026 | G29: inactive | H29: 45505 | I29: 46265 | J29: 29 | K29: 26 | L29: 2 | M29: 5288796 | N29: 0 | O29: 15000 | P29: 750000 | R29: 5214042 | S29: Hari Kerja: 29 / 26 x 5288796 | T29: Total jam lembur yang disetujui = 2
A30: 29 | B30: Yeni Angraini | C30: SPG/SPB Toko | D30: MAKASSAR | E30: MAKASSAR - HOKKY HOUSE WARE | F30: 25 Jul 2026 - 24 Aug 2026 | G30: inactive | H30: 45855 | I30: 46265 | J30: 24 | K30: 26 | M30: 4148179 | N30: 0 | O30: 15000 | P30: 440000 | R30: 3424088 | S30: Hari Kerja: 24 / 26 x 4148179
A31: 30 | B31: AgusTia ningRum | C31: SPG/SPB Toko | D31: BANJARMASIN | E31: BANJARMASIN - NUANSA PANGKALANBUN | F31: 25 Jul 2026 - 24 Aug 2026 | G31: inactive | H31: 45546 | I31: 46265 | J31: 27 | K31: 26 | M31: 3909005 | N31: 0 | O31: 15000 | R31: #VALUE! | S31: Hari Kerja: 27 / 26 x 3909005
A32: 31 | B32: Mesrawati Lase | C32: SPG/SPB Toko | D32: MEDAN | E32: MEDAN - IRAMA HOUSEWARE | F32: 25 Jul 2026 - 24 Aug 2026 | G32: inactive | H32: 45541 | I32: 46265 | J32: 25 | K32: 26 | M32: 4335198 | N32: 0 | O32: 15000 | R32: #VALUE! | S32: Hari Kerja: 25 / 26 x 4335198
A33: 32 | B33: Jesty Ananda | C33: SPG/SPB Toko | D33: SAMARINDA | E33: SAMARINDA - NUANSA TENGGARONG | F33: 25 Jul 2026 - 24 Aug 2026 | G33: inactive | H33: 45553 | I33: 46265 | J33: 28 | K33: 26 | M33: 3991797 | N33: 0 | O33: 15000 | R33: #VALUE! | S33: Hari Kerja: 28 / 26 x 3991797
A34: 33 | B34: Firanda | C34: SPG/SPB Toko | D34: PALEMBANG | E34: PALEMBANG - MDP SUPERSTORE | F34: 25 Jul 2026 - 24 Aug 2026 | G34: inactive | H34: 45567 | I34: 46265 | J34: 27 | K34: 26 | M34: 4192837 | N34: 0 | O34: 15000 | P34: 750000 | R34: 3639100 | S34: Hari Kerja: 27 / 26 x 4192837
A35: 34 | B35: Yustika Kaimuddin | C35: SPG/SPB Toko | D35: MAKASSAR | E35: MAKASSAR - MAXI ALAUDDIN | F35: 25 Jul 2026 - 24 Aug 2026 | G35: inactive | H35: 45566 | I35: 46265 | J35: 27 | K35: 26 | M35: 4148179 | N35: 0 | O35: 15000 | R35: #VALUE! | S35: Hari Kerja: 27 / 26 x 4148179
A36: 35 | B36: Dinda Sri Rahayu | C36: SPG/SPB Toko | D36: BANDUNG | E36: BANDUNG - LOGIN MEGASTORE (ABC) | F36: 25 Jul 2026 - 24 Aug 2026 | G36: inactive | H36: 45576 | I36: 46265 | J36: 28 | K36: 26 | M36: 4737678 | N36: 0 | O36: 15000 | P36: 750000 | R36: 4387115 | S36: Hari Kerja: 28 / 26 x 4737678
A37: 36 | B37: Owen Jehezkiel Wijaya | C37: SPG/SPB Toko | D37: SURABAYA | E37: SURABAYA - SUPER MURAH SURABAYA 2 | F37: 25 Jul 2026 - 24 Aug 2026 | G37: inactive | H37: 45579 | I37: 46265 | J37: 29 | K37: 26 | M37: 5288796 | N37: 0 | O37: 15000 | R37: #VALUE! | S37: Hari Kerja: 29 / 26 x 5288796
A38: 37 | B38: Selviana | C38: SPG/SPB Toko | D38: SAMARINDA | E38: SAMARINDA - TOKO SURYA JAYA | F38: 25 Jul 2026 - 24 Aug 2026 | G38: inactive | H38: 45628 | I38: 46265 | J38: 27 | K38: 26 | M38: 3991797 | N38: 0 | O38: 15000 | R38: #VALUE! | S38: Hari Kerja: 27 / 26 x 3991797
A39: 38 | B39: Christiana Dwi Jayanti | C39: SPG/SPB Toko | D39: SEMARANG | E39: SEMARANG - A TAKRIB LIFE STYLE | F39: 25 Jul 2026 - 24 Aug 2026 | G39: inactive | H39: 45627 | I39: 46265 | J39: 27 | K39: 26 | M39: 2827593 | N39: 0 | O39: 15000 | R39: #VALUE! | S39: Hari Kerja: 27 / 26 x 2827593
A40: 39 | B40: Gusti Rusmiami | C40: SPG/SPB Toko | D40: BANJARMASIN | E40: BANJARMASIN - NUANSA ELEKTRONIK TANJUNG | F40: 25 Jul 2026 - 24 Aug 2026 | G40: inactive | H40: 45627 | I40: 46265 | J40: 27 | K40: 26 | M40: 3827935 | N40: 0 | O40: 15000 | R40: #VALUE! | S40: Hari Kerja: 27 / 26 x 3827935
...

Sheet data StaffInc
A1: Employee ID* | B1: Name* | C1: Phone Number* | D1: Email | E1: Position | F1: Gender | G1: KTP Number | H1: Date of Birth | I1: Birth Place Code | J1: Religion | K1: Blood Type | L1: Marital Status | M1: Domicile Province Code | N1: Domicile City Code | O1: Domicile District Code | P1: Domicile Address | Q1: Status* | R1: Join Date | S1: Deactivation Type | T1: Receive Resignation Request At | U1: Last Day | V1: Inactive Reason | W1: Inactive Notes | X1: External Employee ID | Y1: Entity | Z1: Deployment Province Code | AA1: Deployment City Code | AB1: Deployment District Code | AC1: Deployment Group | AD1: Employement type | AE1: Contract type | AF1: Digital Signature ID | AG1: Active Contract start date | AH1: Active Contract end date | AI1: Project | AJ1: Branch ID | AK1: Payroll Group ID | AL1: Leave Policy | AM1: BPJS TK Number | AN1: BPJS Kesehatan Number | AO1: NPWP | AP1: BPJS Kesehatan Eligibility | AQ1: BPJS TK Eligibility | AR1: BPJS TK Membership | AS1: BPJS TK Program | AT1: PTKP Status | AU1: Payment Channel Type | AV1: Payment Channel Code | AW1: Payment Account Name | AX1: Payment Account Number | AY1: Emergency Contact’s Full Name | AZ1: Emergency Contact’s Phone Number | BA1: Emergency Contact’s Address | BB1: Emergency Contact's Relation to Employee
A2: 187078 | B2: Anggiza Gana Pawestri | C2: 87887345099 | D2: anggi_zhie@yahoo.com | E2: SPG/SPB Toko | F2: Female | G2: 3175104409860007 | H2: 31659 | I2: 694 | J2: Islam | K2: O | L2: Kawin | M2: 11 | N2: 694 | O2: 2006 | P2: Jl. Buni Malaka, Rt. 006, Rw. 008, Kel. Munjul, Kec. Cipayung | Q2: Inactive | R2: 43409 | S2: Now | U2: 46265 | W2: selesai project | X2: 20181101 | Y2: PT Kita Mitra Indonesia | Z2: 12 | AA2: 721 | AD2: Full-Time | AE2: Kemitraan | AG2: 46167 | AH2: 46265 | AJ2: 11073 | AM2: 21033169232 | AN2: 1737584458 | AO2: 589400142009000 | AP2: Inactive | AQ2: Active | AR2: BPU | AS2: JKM;JKK | AT2: TK/1 | AU2: Bank | AV2: BCA | AW2: ANGGIZA GANA PAWESTRI | AX2: 8691115984 | AY2: Rangga | AZ2: 85772005148 | BA2: Jl.buni malaka GG mushola 1 Rt06/08 no 15 | BB2: Suami
A3: 187079 | B3: Annisa | C3: 85754771101 | D3: annisaauliani11@gmail.com | E3: SPG/SPB Toko | F3: Female | G3: 6.3710251e+15 | H3: 33553 | I3: 891 | J3: Islam | K3: O | L3: Kawin | M3: 22 | N3: 891 | O3: 5055 | P3: Keramat Raya Gg Satu Dua Rt.10 No.37D Kecamatan Banjarmasin Timur Kelurahan Sungai Bilu Banjarmasin 70236 | Q3: Inactive | R3: 42826 | S3: Now | U3: 46265 | W3: selesai project | X3: 20170401 | Y3: PT Kita Mitra Indonesia | Z3: 22 | AA3: 891 | AD3: Full-Time | AE3: Kemitraan | AG3: 46167 | AH3: 46265 | AJ3: 11060 | AM3: 23048929410 | AN3: 2044139477 | AO3: 755898756731000 | AP3: Inactive | AQ3: Active | AR3: BPU | AS3: JKM;JKK | AT3: K/3 | AU3: Bank | AV3: BCA | AW3: ANNISA | AX3: 511915910 | AY3: rini yulianti | AZ3: 82150088297 | BA3: jl keramat gg satu dua rt.10 no.37d | BB3: Ibu
A4: 187085 | B4: Firda Duri Yatinal Ulya | C4: 82128843818 | D4: firdaduriatinalulya@gmail.com | E4: SPG/SPB Toko | F4: Female | G4: 6472056708950005 | H4: 34938 | I4: 901 | J4: Islam | L4: Belum Kawin | M4: 23 | N4: 901 | O4: 1418 | P4: Jl. Pemuda 2 Gg. Pendawa Blok. E. No. 86, Rt. 012, Rw.000, Kel. Temindung Permai, Kec. Sungai Pinang | Q4: Inactive | R4: 43777 | S4: Now | U4: 46265 | W4: selesai project | X4: 20191101 | Y4: PT Kita Mitra Indonesia | Z4: 23 | AA4: 901 | AD4: Full-Time | AE4: Kemitraan | AG4: 46167 | AH4: 46265 | AJ4: 11113 | AM4: 23048929329 | AN4: 2265201641 | AO4: 940212715722000 | AP4: Inactive | AQ4: Active | AR4: BPU | AS4: JKM;JKK | AT4: TK/0 | AU4: Bank | AV4: BCA | AW4: FIRDA DURI YATINAL ULYA | AX4: 7935297133 | AY4: Ani | AZ4: 85845230207 | BA4: jl.gelatik blok.c | BB4: Saudara Kandung
A5: 187089 | B5: Elisa Putra Afdiono | C5: 89686949505 | D5: zolla041123@gmail.com | E5: SPG/SPB Toko | F5: Female | G5: 3578024803960005 | H5: 35132 | I5: 801 | J5: Islam | K5: O | L5: Kawin | M5: 15 | N5: 801 | O5: 3921 | P5: Margorejo 2-G/32, Rt. 004, Rw. 003, Kel. Margorejo, Kec. Wonocolo | Q5: Inactive | R5: 44077 | S5: Now | U5: 46265 | W5: selesai project | X5: 20200902 | Y5: PT Kita Mitra Indonesia | Z5: 15 | AA5: 801 | AD5: Full-Time | AE5: Kemitraan | AG5: 46167 | AH5: 46265 | AJ5: 11202 | AM5: 23048929493 | AN5: 786612418 | AO5: 726397177609000 | AP5: Inactive | AQ5: Active | AR5: BPU | AS5: JKM;JKK | AT5: TK/0 | AU5: Bank | AV5: BCA | AW5: ELISA PUTRA AFDIONO | AX5: 5600289308 | AY5: andre | AZ5: 8990008817 | BA5: margorejo 2g no 32 | BB5: Suami
A6: 187090 | B6: I Ketut Sugiarta | C6: 82193339184 | D6: sugiartha9977@gmail.com | E6: SPG/SPB Toko | F6: Male | G6: 7208090909970002 | H6: 35682 | I6: 930 | J6: Hindu | K6: O | L6: Belum Kawin | M6: 26 | N6: 930 | O6: 5503 | P6: Dusun Iv , Rt. 000 , Rw. 000 , Kel. Tolai Barat , Kec. Torue - Sulawesi Tengah | Q6: Inactive | R6: 44753 | S6: Now | U6: 46265 | W6: selesai project | X6: 20220703 | Y6: PT Kita Mitra Indonesia | Z6: 27 | AA6: 957 | AD6: Full-Time | AE6: Kemitraan | AG6: 46198 | AH6: 46265 | AJ6: 11091 | AM6: 23048929451 | AN6: 2392202924 | AO6: 437589070831000 | AP6: Inactive | AQ6: Active | AR6: BPU | AS6: JKM;JKK | AT6: TK/0 | AU6: Bank | AV6: BCA | AW6: I KETUT SUGIARTA | AX6: 7795175946
A7: 187092 | B7: Adelina Astuti | C7: 85849233099 | D7: adelinemeidian@gmail.com | E7: SPG/SPB Outlet | F7: Female | G7: 3207195305920001 | H7: 33737 | I7: 704 | J7: Islam | K7: AB | L7: Belum Kawin | M7: 12 | N7: 704 | O7: 2256 | P7: Dusun Tamansari , Rt. 012 , Rw. 004 , Kel. Kertahayu , Kec. Pamarican - Jawa Barat | Q7: Inactive | R7: 44852 | S7: Now | U7: 46265 | V7: Finished - End of Contract | W7: selesai project | X7: 20221006 | Y7: PT Kita Mitra Indonesia | Z7: 11 | AA7: 697 | AD7: Full-Time | AE7: Kemitraan | AG7: 46167 | AH7: 46265 | AJ7: 11354 | AN7: 437862701 | AO7: 614250264442000 | AP7: Inactive | AQ7: Active | AR7: BPU | AS7: JKM;JKK | AT7: TK/0 | AU7: Bank | AV7: BCA | AW7: ADELINA ASTUTI | AX7: 5910185235
A8: 187093 | B8: Ari Kusumawati | C8: 85780008440 | D8: nayarengganis25@gmail.com | E8: SPG/SPB Outlet | F8: Female | G8: 3171026709890003 | H8: 32778 | I8: 695 | J8: Islam | K8: O | L8: Belum Kawin | M8: 11 | N8: 695 | O8: 1966 | P8: Jl. Gn Sahari Ix , Rt. 005 , Rw. 004 , Kel. Gunung Sahari Utara , Kec. Sawah Besar - Jakarta Pusat | Q8: Inactive | R8: 44844 | S8: Now | U8: 46265 | W8: selesai project | X8: 20221004 | Y8: PT Kita Mitra Indonesia | Z8: 11 | AA8: 697 | AD8: Full-Time | AE8: Kemitraan | AG8: 46167 | AH8: 46265 | AJ8: 11354 | AM8: 17000717391 | AN8: 373457902 | AO8: 984389981026000 | AP8: Inactive | AQ8: Active | AR8: BPU | AS8: JKM;JKK | AT8: TK/0 | AU8: Bank | AV8: BCA | AW8: ARI KUSUMAWATI | AX8: 6840428964
A9: 187095 | B9: Firda Nur Agustin Cahyani | C9: 87842322685 | D9: firdanac1608@gmail.com | E9: SPG/SPB Toko | F9: Female | G9: 3205055608020002 | H9: 37484 | I9: 702 | J9: Islam | K9: A | L9: Belum Kawin | M9: 12 | N9: 702 | O9: 2161 | P9: Kp. Leuwi Daun , Rt. 003 , Rw. 008 , Kel. Haurpanggung , Kec. Tarogong Kidul - Jawa Barat | Q9: Inactive | R9: 44858 | S9: Now | U9: 46265 | W9: selesai project | X9: 20221008 | Y9: PT Kita Mitra Indonesia | Z9: 12 | AA9: 702 | AD9: Full-Time | AE9: Kemitraan | AG9: 46167 | AH9: 46265 | AJ9: 11049 | AM9: 23048929402 | AN9: 3045761223 | AO9: 637892589443000 | AP9: Inactive | AQ9: Active | AR9: BPU | AS9: JKM;JKK | AT9: TK/0 | AU9: Bank | AV9: BCA | AW9: FIRDA NUR AGUSTIN CAHYAN | AX9: 4460703641
A10: 187096 | B10: Habib Mustopa | C10: 88985069845 | D10: habibmustopa25@gmail.com | E10: SPG/SPB Toko | F10: Male | G10: 3205312107020002 | H10: 37458 | I10: 702 | J10: Islam | K10: A | L10: Belum Kawin | M10: 12 | N10: 702 | O10: 2187 | P10: Kp Cihikeu , Rt. 001 , Rw. 003 , Kel. Cihikeu , Kec. Bungbulang - Jawa Barat | Q10: Inactive | R10: 44911 | S10: Now | U10: 46265 | W10: selesai project | X10: 20221201 | Y10: PT Kita Mitra Indonesia | Z10: 13 | AA10: 757 | AD10: Full-Time | AE10: Kemitraan | AG10: 46198 | AH10: 46265 | AJ10: 11126 | AM10: 23048929386 | AN10: 1198164565 | AO10: 623212982423000 | AP10: Inactive | AQ10: Active | AR10: BPU | AS10: JKM;JKK | AT10: TK/0 | AU10: Bank | AV10: BCA | AW10: HABIB MUSTOPA | AX10: 2801851268 | AY10: imas masliah | AZ10: 85759557515 | BA10: Jln Cihikeu Desa Cihikeu Kec Bungbulang garut | BB10: Ibu
A11: 187104 | B11: Faisol Adha | C11: 85748348360 | D11: Faisol.adha03@gmail.com | E11: SPG/SPB Outlet | F11: Male | G11: 3506052009940003 | H11: 34597 | I11: 794 | J11: Islam | K11: A | L11: Belum Kawin | M11: 15 | N11: 770 | O11: 3380 | P11: Dsn. Pule Utara, Rt. 002, Rw. 001, Kel. Pule. Kec. Kandat | Q11: Inactive | R11: 45147 | S11: Now | U11: 46265 | W11: selesai project | X11: 20230804 | Y11: PT Kita Mitra Indonesia | Z11: 15 | AA11: 801 | AD11: Full-Time | AE11: Kemitraan | AG11: 46167 | AH11: 46265 | AJ11: 11194 | AM11: 21073634251 | AN11: 1642981026 | AO11: 669091779655000 | AP11: Inactive | AQ11: Active | AR11: BPU | AS11: JKM;JKK | AT11: TK/0 | AU11: Bank | AV11: BCA | AW11: FAISOL ADHA | AX11: 8220741924
A12: 187108 | B12: Fitri Wulandari | C12: 85753994944 | D12: wulan.rhevian22@gmail.com | E12: SPG/SPB Toko | F12: Female | G12: 6303036208870004 | H12: 32011 | I12: 773 | J12: Islam | K12: O | L12: Belum Kawin | M12: 22 | N12: 891 | O12: 5056 | P12: Jl. Ampera III Ujung, Rt. 038, Rw. 003, Kel. Basirih, Kec. Banjarmasin Barat | Q12: Inactive | R12: 45323 | S12: Now | U12: 46265 | W12: selesai project | X12: 20240204 | Y12: PT Kita Mitra Indonesia | Z12: 22 | AA12: 891 | AD12: Full-Time | AE12: Kemitraan | AG12: 46228 | AH12: 46265 | AJ12: 11065 | AM12: 24087351821 | AN12: 3107840848 | AO12: 609448345731000 | AP12: Inactive | AQ12: Active | AR12: BPU | AS12: JKM;JKK | AT12: TK/0 | AU12: Bank | AV12: BCA | AW12: FITRI WULANDARI | AX12: 8275329891
A13: 187109 | B13: Hendrika Buwa | C13: 85246946597 | D13: buwaqhendrika@gmail.com | E13: SPG/SPB Toko | F13: Female | G13: 6472064110950005 | H13: 34973 | I13: 899 | J13: Islam | K13: B | L13: Kawin | M13: 23 | N13: 901 | O13: 5164 | P13: Jl. Kh Agus Salim Gg. Tanjung/49, Rt. 036, Rw. 000, Kel. Sungai Pinang Luar, Samarinda Kota | Q13: Inactive | R13: 45327 | S13: Scheduled | T13: 46244 | U13: 46259 | V13: Resign - Get New Job | X13: 20240206 | Y13: PT Kita Mitra Indonesia | Z13: 23 | AA13: 901 | AD13: Full-Time | AE13: Kemitraan | AG13: 46167 | AH13: 46258 | AJ13: 11114 | AM13: 22033920558 | AN13: 1282675533 | AO13: 844473009722000 | AP13: Inactive | AQ13: Active | AR13: BPU | AS13: JKM;JKK | AT13: K/2 | AU13: Bank | AV13: BCA | AW13: HENDRIKA BUWA | AX13: 7935355427
A14: 187120 | B14: Agus Tianing Rum | C14: 811522178 | D14: ningrumtia03@gmail.com | E14: SPG/SPB Toko | F14: Female | G14: 3320136308000005 | H14: 36395 | I14: 744 | J14: Islam | K14: O | L14: Cerai hidup | M14: 21 | N14: 866 | O14: 4773 | P14: Jl. Kasan Rejo Rt/Rw.018/000, Kel. Sidorejo, Kec.Arut Selatan Kota.Waringin Barat, Kalimantan Tengah | Q14: Inactive | R14: 45546 | S14: Now | U14: 46265 | V14: Finished - End of Contract | W14: selesai project | X14: 20240909 | Y14: PT Kita Mitra Indonesia | Z14: 22 | AA14: 891 | AD14: Full-Time | AE14: Kemitraan | AG14: 46198 | AH14: 46265 | AJ14: 11063 | AM14: 24160946190 | AN14: 2434254276 | AO14: 500765599713000 | AP14: Inactive | AQ14: Active | AR14: BPU | AS14: JKM;JKK | AT14: TK/1 | AU14: Bank | AV14: BCA | AW14: AGUS TIANING RUM | AX14: 8585226544
A15: 187122 | B15: Jesty Ananda | C15: 895338933809 | D15: jestyananda903@gmail.com | E15: SPG/SPB Toko | F15: Female | G15: 6402064701040005 | H15: 37993 | I15: 895 | J15: Protestan | K15: B | L15: Belum Kawin | M15: 23 | N15: 895 | O15: 5079 | P15: Jl. Gunung Pegat No.13 Rt/Rw.035/000, Kel. Melayu, Kec. Tenggarong, Kab. Kutai Kartanegara, Kalimantan Timur | Q15: Inactive | R15: 45553 | S15: Now | U15: 46265 | V15: Finished - End of Contract | X15: 20240912 | Y15: PT Kita Mitra Indonesia | Z15: 23 | AA15: 901 | AD15: Full-Time | AE15: Kemitraan | AG15: 46167 | AH15: 46265 | AJ15: 11115 | AM15: 24160946208 | AO15: 200081255728000 | AP15: Inactive | AQ15: Active | AR15: BPU | AS15: JKM;JKK | AT15: TK/0 | AU15: Bank | AV15: BCA | AW15: JESTY ANANDA | AX15: 8145371186 | AY15: Iin paramitha utami | AZ15: 85350032333 | BA15: jln gn pegat,gg 01C,rumah kontrakan | BB15: Saudara Kandung
A16: 187123 | B16: Firanda | C16: 83872915839 | D16: fanda5833@gmail.com | E16: SPG/SPB Toko | F16: Female | G16: 1607064512060003 | H16: 39056 | J16: Islam | L16: Belum Kawin | M16: 6 | N16: 642 | O16: 730 | P16: Dusun Iv Desa Sungai Pinang Rt/Rw.024/000 Kel. Sungaipinang, Kec. Rambutan, Kab. Banyuasin, Sumatera Selatan. | Q16: Inactive | R16: 45567 | S16: Now | U16: 46265 | W16: selesai project | X16: 20241005 | Y16: PT Kita Mitra Indonesia | Z16: 6 | AA16: 649 | AD16: Full-Time | AE16: Kemitraan | AG16: 46167 | AH16: 46265 | AJ16: 11107 | AM16: 24160946232 | AP16: Inactive | AQ16: Active | AR16: BPU | AS16: JKM;JKK | AT16: TK/0 | AU16: Bank | AV16: BCA | AW16: FIRANDA | AX16: 8435689139
A17: 187126 | B17: Dinda Sri Rahayu | C17: 89659753361 | D17: dindasrirahayu9@gmail.com | E17: SPG/SPB Toko | F17: Female | G17: 3204355911990003 | H17: 36483 | I17: 701 | J17: Islam | K17: O | L17: Belum Kawin | M17: 12 | N17: 701 | O17: 2149 | P17: Kp. Pangsor Rt 008, Rw 010. Kel.Sukamantri. Kec.Paseh, Kab. Bandung, Jawa Barat. | Q17: Inactive | R17: 45576 | S17: Now | U17: 46265 | W17: selesai project | X17: 20241011 | Y17: PT Kita Mitra Indonesia | Z17: 12 | AA17: 718 | AD17: Full-Time | AE17: Kemitraan | AG17: 46167 | AH17: 46265 | AJ17: 11055 | AM17: 24134943919 | AO17: 937047769444000 | AP17: Inactive | AQ17: Active | AR17: BPU | AS17: JKM;JKK | AT17: TK/0 | AU17: Bank | AV17: BCA | AW17: DINDA SRI RAHAYU | AX17: 3760618135 | AY17: nunung | AZ17: 89514887715 | BA17: kp. pangsor Rt.08/10 | BB17: Ibu
A18: 187132 | B18: Gusti Rusmiami | C18: 82253031413 | D18: ammygusti@gmail.com | E18: SPG/SPB Toko | F18: Female | G18: 6302064111930005 | H18: 34274 | J18: Islam | K18: A | L18: Kawin | M18: 22 | N18: 888 | O18: 3169 | P18: Komplek Loyang Indah Rt/Rw.011/00 Kel. Jangkung, Kec. Tanjung, Kab. Tabalong, Kalimantan Selatan. | Q18: Inactive | R18: 45627 | S18: Now | U18: 46265 | W18: selesai project | X18: 20241202 | Y18: PT Kita Mitra Indonesia | Z18: 22 | AA18: 891 | AD18: Full-Time | AE18: Kemitraan | AG18: 46167 | AH18: 46265 | AJ18: 11064 | AM18: 24217518620 | AO18: 147219026735000 | AP18: Inactive | AQ18: Active | AR18: BPU | AS18: JKM;JKK | AT18: TK/0 | AU18: Bank | AV18: BCA | AW18: GUSTI RUSMIAMI | AX18: 8695108539 | AY18: Rija Husaini | AZ18: 8125450053 | BA18: Jl Komp Loyan Indah Rt 11 | BB18: Suami
A19: 187135 | B19: Ela Siska Ariatun | C19: 82358812078 | D19: elasiska01@gmail.com | E19: SPG/SPB Toko | F19: Female | G19: 6401044908020005 | H19: 37477 | I19: 799 | J19: Islam | K19: B | L19: Kawin | M19: 23 | N19: 893 | O19: 5067 | P19: Jl. Modang Gg Rukun Rt/Rw.005/002 Kel. Tanah Grogot, Kec. Tanah Grogot, Kab. Paser, Kalimantan Timur. | Q19: Inactive | R19: 45647 | S19: Now | U19: 46265 | W19: selesai project | X19: 20241218 | Y19: PT Kita Mitra Indonesia | Z19: 23 | AA19: 901 | AD19: Full-Time | AE19: Kemitraan | AG19: 46198 | AH19: 46265 | AJ19: 11117 | AM19: 24217518612 | AN19: 2288253497 | AO19: 618137277726000 | AP19: Inactive | AQ19: Active | AR19: BPU | AS19: JKM;JKK | AT19: TK/0 | AU19: Bank | AV19: BCA | AW19: ELA SISKA ARIATUN | AX19: 7815831241
A20: 187138 | B20: Ainun Jariyah | C20: 895608199789 | D20: Program.ainun@gmail.com | E20: SPG/SPB Toko | F20: Female | G20: 6371014305950008 | H20: 34822 | I20: 891 | J20: Islam | K20: AB | L20: Belum Kawin | M20: 22 | N20: 891 | O20: 5054 | P20: Jl. Kelayan A Gg. Sidodadi. Rt/Rw. 011/001. Kel. Murung Raya. Kec. Banjarmasin Selatan | Q20: Inactive | R20: 45685 | S20: Now | U20: 46265 | V20: Finished - End of Contract | W20: selesai project | X20: 20250120 | Y20: PT Kita Mitra Indonesia | Z20: 22 | AA20: 891 | AD20: Full-Time | AE20: Kemitraan | AG20: 45901 | AH20: 46265 | AJ20: 11066 | AO20: 910303221736000 | AP20: Inactive | AQ20: Active | AR20: BPU | AS20: JKM;JKK | AT20: TK/0 | AU20: Bank | AV20: BCA | AW20: AINUN JARIAH | AX20: 7820819785 | AY20: sam | AZ20: 81348153855 | BA20: Kelayan A gang sidodadi | BB20: Ayah
A21: 187144 | B21: Fhadila Rahmatika Haya | C21: 85725663034 | D21: fadhilaarh19@gmail.com | E21: SPG/SPB Toko | F21: Female | G21: 3372035909000002 | H21: 36788 | I21: 755 | J21: Islam | K21: B | L21: Belum Kawin | M21: 13 | N21: 755 | O21: 3179 | P21: Sangkrah Rt/02 Rw/11. Kel. Sangkrah Kec. Pasar Kliwon | Q21: Inactive | R21: 45685 | S21: Now | U21: 46265 | W21: selesai project | X21: 20250121 | Y21: PT Kita Mitra Indonesia | Z21: 13 | AA21: 757 | AD21: Full-Time | AE21: Kemitraan | AG21: 46198 | AH21: 46265 | AJ21: 11145 | AN21: 1692987175 | AO21: 508108073526000 | AP21: Inactive | AQ21: Active | AR21: BPU | AS21: JKM;JKK | AT21: TK/0 | AU21: Bank | AV21: BCA | AW21: FHADILA RAHMATIKA HAYA | AX21: 1530616408
